2020-02-04 14:25:39.749 parsl.dataflow.dflow:83 [DEBUG]  Starting DataFlowKernel with config
Config(
    app_cache=True, 
    checkpoint_files=None, 
    checkpoint_mode=None, 
    checkpoint_period=None, 
    data_management_max_threads=10, 
    executors=[ThreadPoolExecutor(
        label='threads', 
        managed=True, 
        max_threads=20, 
        storage_access=None, 
        thread_name_prefix='', 
        working_dir=None
    )], 
    initialize_logging=True, 
    lazy_errors=True, 
    max_idletime=120.0, 
    monitoring=None, 
    retries=0, 
    run_dir='runinfo', 
    strategy='simple', 
    usage_tracking=False
)
2020-02-04 14:25:39.749 parsl.dataflow.dflow:84 [INFO]  Parsl version: 0.9.0
2020-02-04 14:25:39.750 parsl.dataflow.usage_tracking.usage:126 [DEBUG]  Tracking status: False
2020-02-04 14:25:39.750 parsl.dataflow.usage_tracking.usage:127 [DEBUG]  Testing mode   : False
2020-02-04 14:25:39.750 parsl.dataflow.dflow:110 [INFO]  Run id is: bca5dd4b-0916-422b-96e1-3fba524fa85a
2020-02-04 14:25:39.822 parsl.dataflow.memoization:52 [INFO]  App caching initialized
2020-02-04 14:25:39.822 parsl.dataflow.strategy:125 [DEBUG]  Scaling strategy: simple
2020-02-04 14:25:39.907 parsl.dataflow.dflow:484 [DEBUG]  Adding output dependencies
2020-02-04 14:25:39.908 parsl.dataflow.dflow:708 [INFO]  Task 0 submitted for App star_index, waiting on tasks []
2020-02-04 14:25:39.908 parsl.dataflow.dflow:714 [DEBUG]  Task 0 set to pending state with AppFuture: <AppFuture super=<AppFuture at 0x7f2ad3a39208 state=pending>>
2020-02-04 14:25:39.909 parsl.dataflow.dflow:452 [INFO]  Task 0 launched on executor threads
2020-02-04 14:25:39.910 parsl.app.bash.1580844339.908773:54 [DEBUG]  Executable: 'STAR --runThreadN 1 --runMode genomeGenerate --genomeDir  "/home/users/ellenrichards/test_run_1/s008_c41703_g1_i1_m8507/gd" --genomeFastaFiles "/home/users/ellenrichards/test_run_1/s008_c41703_g1_i1_m8507.fasta" --genomeSAindexNbases 2'
2020-02-04 14:25:39.920 parsl.app.errors:158 [DEBUG]  Reraising exception of type <class 'parsl.app.errors.AppFailure'>
2020-02-04 14:25:39.920 parsl.dataflow.dflow:257 [DEBUG]  Task 0 failed
2020-02-04 14:25:39.920 parsl.dataflow.dflow:279 [ERROR]  Task 0 failed after 0 retry attempts
Traceback (most recent call last):
  File "/local/cluster/lib/python3.6/site-packages/parsl/dataflow/dflow.py", line 254, in handle_exec_update
    res.reraise()
  File "/local/cluster/lib/python3.6/site-packages/parsl/app/errors.py", line 163, in reraise
    reraise(t, v, tb)
  File "/local/cluster/lib/python3.6/site-packages/six.py", line 692, in reraise
    raise value.with_traceback(tb)
  File "/local/cluster/lib/python3.6/site-packages/parsl/app/errors.py", line 172, in wrapper
    return func(*args, **kwargs)
  File "/local/cluster/lib/python3.6/site-packages/parsl/app/bash.py", line 101, in remote_side_bash_executor
    raise pe.AppFailure("[{}] App failed with exit code: {}".format(func_name, proc.returncode), proc.returncode)
parsl.app.errors.AppFailure: ('[star_index] App failed with exit code: 127', 127)
2020-02-04 14:25:39.922 parsl.app.errors:158 [DEBUG]  Reraising exception of type <class 'parsl.app.errors.AppFailure'>
2020-02-04 14:25:42.416 parsl.dataflow.dflow:864 [INFO]  DFK cleanup initiated
2020-02-04 14:25:42.416 parsl.dataflow.dflow:750 [INFO]  Summary of tasks in DFK:
2020-02-04 14:25:42.416 parsl.dataflow.dflow:781 [INFO]  Tasks in state States.failed: 0
2020-02-04 14:25:42.417 parsl.dataflow.dflow:788 [INFO]  End of summary
2020-02-04 14:25:42.417 parsl.dataflow.dflow:888 [INFO]  Terminating flow_control and strategy threads
2020-02-04 14:25:42.417 parsl.executors.threads:96 [DEBUG]  Done with executor shutdown
2020-02-04 14:25:42.417 parsl.executors.threads:96 [DEBUG]  Done with executor shutdown
2020-02-04 14:25:42.418 parsl.dataflow.dflow:920 [INFO]  DFK cleanup complete
